
0it [00:00, ?it/s]

0it [00:00, ?it/s][ATraceback (most recent call last):
  File "/home/hepe00001/miniconda3/envs/layout/lib/python3.8/site-packages/torchvision/datasets/utils.py", line 79, in download_url
    opener.retrieve(
  File "/home/hepe00001/miniconda3/envs/layout/lib/python3.8/urllib/request.py", line 1828, in retrieve
    fp = self.open(url, data)
  File "/home/hepe00001/miniconda3/envs/layout/lib/python3.8/urllib/request.py", line 1794, in open
    return getattr(self, name)(url)
  File "/home/hepe00001/miniconda3/envs/layout/lib/python3.8/urllib/request.py", line 1972, in open_http
    return self._open_generic_http(http.client.HTTPConnection, url, data)
  File "/home/hepe00001/miniconda3/envs/layout/lib/python3.8/urllib/request.py", line 1966, in _open_generic_http
    return self.http_error(
  File "/home/hepe00001/miniconda3/envs/layout/lib/python3.8/urllib/request.py", line 1988, in http_error
    return self.http_error_default(url, fp, errcode, errmsg, headers)
  File "/home/hepe00001/miniconda3/envs/layout/lib/python3.8/urllib/request.py", line 1993, in http_error_default
    raise HTTPError(url, errcode, errmsg, headers, None)
urllib.error.HTTPError: HTTP Error 302: Found

During handling of the above exception, another exception occurred:

Traceback (most recent call last):
  File "/home/hepe00001/deeplayout/DeepLayout/layout_transformer/main.py", line 59, in <module>
    train_dataset = MNISTLayout(args.log_dir, train=True, threshold=args.threshold)
  File "/home/hepe00001/deeplayout/DeepLayout/layout_transformer/dataset.py", line 35, in __init__
    super().__init__(root, train=train, download=download)
  File "/home/hepe00001/miniconda3/envs/layout/lib/python3.8/site-packages/torchvision/datasets/mnist.py", line 79, in __init__
    self.download()
  File "/home/hepe00001/miniconda3/envs/layout/lib/python3.8/site-packages/torchvision/datasets/mnist.py", line 146, in download
    download_and_extract_archive(url, download_root=self.raw_folder, filename=filename, md5=md5)
  File "/home/hepe00001/miniconda3/envs/layout/lib/python3.8/site-packages/torchvision/datasets/utils.py", line 282, in download_and_extract_archive
    download_url(url, download_root, filename, md5)
  File "/home/hepe00001/miniconda3/envs/layout/lib/python3.8/site-packages/torchvision/datasets/utils.py", line 110, in download_url
    raise e
  File "/home/hepe00001/miniconda3/envs/layout/lib/python3.8/site-packages/torchvision/datasets/utils.py", line 92, in download_url
    opener.retrieve(
  File "/home/hepe00001/miniconda3/envs/layout/lib/python3.8/urllib/request.py", line 1828, in retrieve
    fp = self.open(url, data)
  File "/home/hepe00001/miniconda3/envs/layout/lib/python3.8/urllib/request.py", line 1794, in open
    return getattr(self, name)(url)
  File "/home/hepe00001/miniconda3/envs/layout/lib/python3.8/urllib/request.py", line 2003, in open_https
    return self._open_generic_http(self._https_connection, url, data)
  File "/home/hepe00001/miniconda3/envs/layout/lib/python3.8/urllib/request.py", line 1966, in _open_generic_http
    return self.http_error(
  File "/home/hepe00001/miniconda3/envs/layout/lib/python3.8/urllib/request.py", line 1988, in http_error
    return self.http_error_default(url, fp, errcode, errmsg, headers)
  File "/home/hepe00001/miniconda3/envs/layout/lib/python3.8/urllib/request.py", line 1993, in http_error_default
    raise HTTPError(url, errcode, errmsg, headers, None)
urllib.error.HTTPError: HTTP Error 403: Forbidden

0it [00:00, ?it/s]

0it [00:00, ?it/s]
ERROR conda.cli.main_run:execute(125): `conda run bash -c 
  nvidia-smi
  echo $CUDA_VISIBLE_DEVICES
  echo $HOSTNAME
  which python
  python -m pip list
  python /home/hepe00001/deeplayout/DeepLayout/layout_transformer/main.py --data_dir /MNIST --threshold 1 --exp mnist_threshold_1
` failed. (See above for error)
